Workbook

Sheet AWS Substitution Map
A1: NeuralQuant — AWS-First Service Substitution Map
A2: LEGEND: Green = AWS native (fully covered by Activate credits) | Amber = Hybrid (AWS replaces 3rd-party partially) | Red = Eliminated (replaced entirely) | White = Retained (no AWS equivalent)
A3: Original service | B3: AWS native replacement | C3: Service type | D3: Original $/mo | E3: AWS $/mo | F3: Monthly saving $ | G3: 18-mo saving $ | H3: Credit covered? | I3: Notes
A4: EC2 + RDS + Lambda + S3 | B4: EC2 + RDS Multi-AZ + Lambda + S3 + ElastiCache | C4: Compute/Storage | D4: 590 | E4: 720 | F4: =D4-E4 -> -130 | G4: =F4*18 -> -2340 | H4: Yes | I4: AWS Activate credits absorb full cost M1-12. Multi-AZ RDS now correctly budgeted at db.t3.medium. ElastiCache Redis replaces Upstash.
A5: Redis (Upstash — external) | B5: AWS ElastiCache (Redis) — cache.t3.micro | C5: Cache | D5: 50 | E5: 20 | F5: =D5-E5 -> 30 | G5: =F5*18 -> 540 | H5: Yes | I5: ElastiCache included in AWS ecosystem. Cheaper than Upstash at low scale. Covered by Activate credits.
A6: CDN for chart images (external) | B6: AWS CloudFront + S3 | C6: CDN | D6: 29 | E6: 15 | F6: =D6-E6 -> 14 | G6: =F6*18 -> 252 | H6: Yes | I6: CloudFront + S3 already in stack. Marginal add-on cost near zero at early volumes. Activate credits cover.
A7: Cloudflare Pro (WAF + DDoS) — external | B7: AWS WAF + AWS Shield Standard | C7: WAF/DDoS | D7: 100 | E7: 18 | F7: =D7-E7 -> 82 | G7: =F7*18 -> 1476 | H7: Yes | I7: AWS WAF: $5 Web ACL + ~10 rules × $1 + requests. Shield Standard: FREE. Replaces Cloudflare Pro entirely. Activate credits cover.
A8: Snyk dependency scanning — external | B8: Amazon Inspector (EC2 + Lambda + ECR) | C8: Vuln scanning | D8: 50 | E8: 35 | F8: =D8-E8 -> 15 | G8: =F8*18 -> 270 | H8: Yes | I8: Inspector ~$25-45/mo for NQ workload size. Continuous CVE scanning of EC2, Lambda, ECR images. Activate credits cover.
A9: Security logging (CloudTrail+CloudWatch) — already AWS | B9: AWS CloudTrail + CloudWatch (same) | C9: Audit/logging | D9: 40 | E9: 40 | F9: =D9-E9 -> 0 | G9: =F9*18 -> 0 | H9: Yes | I9: No change — already AWS native. Activate credits cover.
A10: AWS Secrets Manager — already AWS | B10: AWS Secrets Manager (same) | C10: Secrets mgmt | D10: 20 | E10: 20 | F10: =D10-E10 -> 0 | G10: =F10*18 -> 0 | H10: Yes | I10: No change — already AWS native. Activate credits cover.
A11: VAPT annual (external vendor) | B11: Amazon Inspector continuous + AWS Security Hub | C11: Continuous VAPT | D11: 0 | E11: 25 | F11: =D11-E11 -> -25 | G11: =F11*18 -> -450 | H11: Yes | I11: Inspector+Security Hub provide continuous assessment replacing point-in-time annual VAPT. Still budget ₹1L for external pen test at launch.
A12: N/A — new | B12: Amazon GuardDuty (threat detection) | C12: Threat detection | D12: 0 | E12: 100 | F12: =D12-E12 -> -100 | G12: =F12*18 -> -1800 | H12: Yes | I12: ML-based threat detection: crypto-mining, credential abuse, data exfil. ~$80-120/mo for NQ workload. Activate credits cover. SEBI audit trail value.
A13: N/A — new | B13: Amazon Macie (PII discovery in S3) | C13: Data privacy | D13: 0 | E13: 15 | F13: =D13-E13 -> -15 | G13: =F13*18 -> -270 | H13: Yes | I13: Scans S3 for PII/financial data. Required for DPDP Act 2023 compliance — auto-detects Aadhaar, PAN, card numbers in S3 buckets.
A14: N/A — new | B14: AWS Security Hub (findings aggregation) | C14: Security posture | D14: 0 | E14: 30 | F14: =D14-E14 -> -30 | G14: =F14*18 -> -540 | H14: Yes | I14: Aggregates GuardDuty + Inspector + WAF findings into single compliance dashboard. SOC 2 Type 1 evidence store.
A15: Supabase Auth (JWT/OAuth/SAML) | B15: Amazon Cognito + Supabase Pro (DB only) | C15: Auth + DB | D15: 599 | E15: 75 | F15: =D15-E15 -> 524 | G15: =F15*18 -> 9432 | H15: No | I15: Cognito handles all auth (JWT, OAuth, SAML/SSO). Supabase drops to Pro ($25/mo) for managed Postgres + RLS only. Cognito free tier: 10K MAU free; $0.015/MAU above that.
... A25: Vercel Pro — external | B25: AWS Amplify Hosting (alternative) | C25: Frontend hosting | D25: 20 | E25: 20 | F25: =D25-E25 -> 0 | G25: =F25*18 -> 0 | H25: No | I25: Vercel Pro retained — Next.js ISR support is superior on Vercel. AWS Amplify is an option but ISR support less mature. No saving here.
A26: Monthly totals | D26: =SUM(D4:D25) -> 1699 | E26: =SUM(E4:E25) -> 1185 | F26: =SUM(F4:F25) -> 514 | G26: =SUM(G4:G25) -> 9252

Sheet AWS Credit Utilisation
A1: NeuralQuant — AWS Activate Credit Utilisation Plan (18 Months)
A2: Assumes AWS Activate Portfolio tier: $100,000 credits over 18 months (VC/accelerator backed). Founders tier: $1,000 only — update B6 if applicable.
A3: Section A — Credit assumptions (blue = editable inputs)
A4: AWS Activate tier | B4: Portfolio (VC/accelerator backed) | C4: Source: aws.amazon.com/activate
A5: Total credits available ($) | B5: 50000 | C5: Source: AWS Activate Portfolio — verified 2026
A6: Credit validity (months) | B6: 18 | C6: Typical Portfolio credit window
A7: Credits per month (average) ($) | B7: =B5/B6 -> 2777.7778 | C7: Derived from above
A8: USD/INR rate | B8: 85 | C8: Update if rate changes
A9: Section B — Month-by-month credit drawdown vs actual AWS spend
A10: AWS service | B10: M1 | C10: M2 | D10: M3 | E10: M4 | F10: M5 | G10: M6 | H10: M7-9 (avg) | I10: M10-18 (avg) | J10: 18-mo total $
A11: EC2 + RDS + Lambda + S3 (base) | B11: 400 | C11: 400 | D11: 400 | E11: 500 | F11: 500 | G11: 720 | H11: 750 | I11: 900 | J11: 13270
A12: ElastiCache Redis | B12: 20 | C12: 20 | D12: 20 | E12: 20 | F12: 20 | G12: 20 | H12: 25 | I12: 35 | J12: 510
A13: CloudFront + S3 (CDN) | B13: 5 | C13: 5 | D13: 5 | E13: 10 | F13: 10 | G13: 15 | H13: 20 | I13: 30 | J13: 380
A14: AWS WAF | B14: 18 | C14: 18 | D14: 18 | E14: 20 | F14: 20 | G14: 22 | H14: 25 | I14: 30 | J14: 461
A15: Amazon Inspector | B15: 25 | C15: 25 | D15: 25 | E15: 30 | F15: 30 | G15: 35 | H15: 40 | I15: 45 | J15: 695
A16: CloudTrail + CloudWatch | B16: 40 | C16: 40 | D16: 40 | E16: 45 | F16: 45 | G16: 50 | H16: 55 | I16: 65 | J16: 1010
A17: Secrets Manager | B17: 20 | C17: 20 | D17: 20 | E17: 20 | F17: 20 | G17: 20 | H17: 20 | I17: 25 | J17: 405
A18: GuardDuty | B18: 80 | C18: 80 | D18: 80 | E18: 90 | F18: 90 | G18: 100 | H18: 110 | I18: 120 | J18: 1930
A19: Amazon Macie | B19: 10 | C19: 10 | D19: 10 | E19: 12 | F19: 12 | G19: 15 | H19: 15 | I19: 18 | J19: 276
A20: AWS Security Hub | B20: 15 | C20: 15 | D20: 15 | E20: 20 | F20: 20 | G20: 25 | H20: 30 | I20: 35 | J20: 515
A21: AWS X-Ray (APM) | B21: 4 | C21: 4 | D21: 4 | E21: 5 | F21: 5 | G21: 6 | H21: 8 | I21: 10 | J21: 142
A22: Route 53 Health Checks | B22: 2 | C22: 2 | D22: 2 | E22: 3 | F22: 3 | G22: 4 | H22: 4 | I22: 5 | J22: 73
... A27: AWS Cost Anomaly Detection | B27: 0 | C27: 0 | D27: 0 | E27: 0 | F27: 0 | G27: 0 | H27: 0 | I27: 0 | J27: 0
A28: Total AWS spend per month / 18-mo | B28: =SUM(B11:B27) -> 646 | C28: =SUM(C11:C27) -> 646 | D28: =SUM(D11:D27) -> 652 | E28: =SUM(E11:E27) -> 805 | F28: =SUM(F11:F27) -> 813 | G28: =SUM(G11:G27) -> 1078 | H28: =SUM(H11:H27) -> 1156 | I28: =SUM(I11:I27) -> 1390 | J28: =SUM(J11:J27) -> 20618
A29: Credits remaining after 18-month AWS spend | J29: =$B$5-J28 -> 29382

Sheet Revised BOM — AWS First
A1: NeuralQuant — Revised BOM v3 (AWS-First, Activate Credits Applied)
A2: AWS Activate Portfolio ($100K) assumed. All AWS-native services covered by credits. Phase-scaled Claude API. All costing errors from v2 carried forward.
A3: Green = covered by AWS credits | Amber = phase-scaled / hybrid | White = non-AWS, retained | Red = risk-flagged
A4: Category | B4: Component | C4: Description / Basis | D4: Monthly ₹ | E4: 18-Mo ₹ | F4: Monthly $ | G4: 18-Mo $ | H4: AWS service? | I4: Status | J4: Notes
A5: Data & AI Engine
A6: Data & AI Engine | B6: Anthropic Claude Sonnet 4.6 API | C6: Phase-scaled: M1-3 ~₹55K, M4-9 ~₹2.2L, M10-18 ~₹7L/mo. See API Assumptions sheet. | D6: credits | E6: credits | F6: credits | G6: credits | H6: No | I6: PHASE | J6: Not an AWS service. See API Cost Assumptions sheet for full phase-scaled breakdown. No AWS equivalent for Anthropic API.
A7: Data & AI Engine | B7: Alpha Vantage Premium | C7: US/global equities fallback. 300 req/min, EOD+intraday. $149/mo. VERIFIED. | D7: 12500 | E7: 225000 | F7: 149 | G7: 2682 | H7: No | I7: RETAIN | J7: No AWS equivalent for market data.
A8: Data & AI Engine | B8: NSE Professional Feed (Cogencis) | C8: Real-time L1 quotes, 500+ NSE tickers. Verify NSE redistribution licence separately. | D8: 50000 | E8: 900000 | F8: 588 | G8: 10588 | H8: No | I8: Risk | J8: ⚠ NSE redistribution licence risk — verify in M1.
A9: Data & AI Engine | B9: CMIE Economic Outlook | C9: India macro data. ₹25K/mo — unverified. Get direct quote in M1. May be ₹35-40K. | D9: 25000 | E9: 450000 | F9: 294 | G9: 5294 | H9: No | I9: Risk | J9: ⚠ Pricing unverified. Budget ₹35K conservatively.
A10: Data & AI Engine | B10: FRED API (US macro — replaces ISM) | C10: CORRECTED: FRED API (Federal Reserve) free. ISM $44/mo subscription eliminated. | D10: 0 | E10: 0 | F10: 0 | G10: 0 | H10: No | I10: RETAIN | J10: Free public API. Saves ₹67,500 vs SOW.
A11: Data & AI Engine | B11: SEC EDGAR + RBI public data | C11: Free-tier APIs. Parser is a Product Build engineering deliverable. | D11: 0 | E11: 0 | F11: 0 | G11: 0 | H11: No | I11: RETAIN | J11: Free.
A12: Data & AI Engine — Subtotal | D12: =SUMIF(D6:D11,">0") -> 87500 | E12: =SUMIF(E6:E11,">0") -> 1575000 | F12: =SUMIF(F6:F11,">0") -> 1031 | G12: =SUMIF(G6:G11,">0") -> 18564
A13: AWS Cloud & Infrastructure
A14: AWS Cloud & Infrastructure | B14: EC2 + RDS Multi-AZ + Lambda + S3 | C14: FastAPI (t3.medium), RDS Multi-AZ from M6, Lambda async, S3 archives. Covered by Activate credits. | D14: credits | E14: credits | F14: credits | G14: credits | H14: Yes | I14: AWS | J14: AWS Activate covers full 18-mo spend (~$720-1,100/mo). Multi-AZ RDS correctly scoped from M6.
A15: AWS Cloud & Infrastructure | B15: AWS ElastiCache (Redis — cache.t3.micro) | C15: PARA-DEBATE response cache. Enables 90% Claude API cache hit. Replaces Upstash. Activate credits cover. | D15: credits | E15: credits | F15: credits | G15: credits | H15: Yes | I15: AWS | J15: Replaces external Upstash ₹4,200/mo. Saves ₹75,600 over 18 months.
A16: AWS Cloud & Infrastructure | B16: AWS CloudFront + S3 (CDN) | C16: Serves dynamically generated score charts + OG images for 1000+ SEO pages. Activate credits cover. | D16: credits | E16: credits | F16: credits | G16: credits | H16: Yes | I16: AWS | J16: Replaces external CDN ₹2,500/mo. Saves ₹45,000 over 18 months.
A17: AWS Cloud & Infrastructure | B17: AWS Backup (automated cross-region DR) | C17: Automated RDS snapshots, S3 replication. Closes BCP gap. ~$10/mo. Activate credits cover. | D17: credits | E17: credits | F17: credits | G17: credits | H17: Yes | I17: AWS | J17: Gap item — previously missing. RPO/RTO capability for SEBI RA audit readiness.
A18: AWS Cloud & Infrastructure | B18: AWS Cost Anomaly Detection + Budgets | C18: Prevents runaway Lambda loops. Free service. Budget alerts per service. | D18: credits | E18: credits | F18: credits | G18: credits | H18: Yes | I18: AWS | J18: Free. Configuration effort only.
A19: AWS Cloud & Infrastructure — Subtotal | D19: =SUMIF(D14:D18,">0") -> 0 | E19: =SUMIF(E14:E18,">0") -> 0 | F19: =SUMIF(F14:F18,">0") -> 0 | G19: =SUMIF(G14:G18,">0") -> 0
A20: AWS Security Suite
A21: AWS Security Suite | B21: AWS WAF (Web Application Firewall) | C21: Replaces Cloudflare Pro. $5 Web ACL + rules + $0.60/M requests. ~$18-30/mo. Activate credits cover. | D21: credits | E21: credits | F21: credits | G21: credits | H21: Yes | I21: AWS | J21: Replaces Cloudflare Pro ₹8,400/mo. Saves ₹1,51,200 over 18 months.
A22: AWS Security Suite | B22: AWS Shield Standard | C22: DDoS protection. FREE — included with all AWS accounts. No cost. | D22: credits | E22: credits | F22: credits | G22: credits | H22: Yes | I22: AWS | J22: Free. Replaces Cloudflare DDoS protection component.
A23: AWS Security Suite | B23: AWS Secrets Manager | C23: API keys, DB credentials, Zerodha/Alpaca OAuth tokens. ~$20/mo. Activate credits cover. | D23: credits | E23: credits | F23: credits | G23: credits | H23: Yes | I23: AWS | J23: No change from v2. Activate credits cover.
A24: AWS Security Suite | B24: Amazon GuardDuty | C24: NEW: ML-based threat detection. Crypto-mining, credential abuse, data exfil. ~$80-120/mo. Credits cover. | D24: credits | E24: credits | F24: credits | G24: credits | H24: Yes | I24: AWS | J24: New gap-fill. SEBI audit trail value. Activate credits cover full 18mo.
A25: AWS Security Suite | B25: Amazon Inspector | C25: Replaces Snyk. Continuous CVE scanning of EC2, Lambda, ECR images. ~$25-45/mo. Credits cover. | D25: credits | E25: credits | F25: credits | G25: credits | H25: Yes | I25: AWS | J25: Replaces external Snyk ₹4,200/mo. Saves ₹75,600 over 18 months.
A26: AWS Security Suite | B26: Amazon Macie | C26: NEW: PII discovery in S3. Detects Aadhaar, PAN, card data. DPDP Act 2023 compliance. ~$15/mo. | D26: credits | E26: credits | F26: credits | G26: credits | H26: Yes | I26: AWS | J26: New. Required for DPDP Act 2023 before Indian user PII collection begins.
A27: AWS Security Suite | B27: CloudTrail + CloudWatch (audit + logging) | C27: API audit trail, anomaly alarms. SOC 2 Type 1 evidence. ~$40-65/mo. Activate credits cover. | D27: credits | E27: credits | F27: credits | G27: credits | H27: Yes | I27: AWS | J27: No change. Activate credits cover.
A28: AWS Security Suite | B28: AWS Security Hub | C28: NEW: Aggregates GuardDuty + Inspector + WAF findings. SOC 2 compliance dashboard. ~$25-35/mo. | D28: credits | E28: credits | F28: credits | G28: credits | H28: Yes | I28: AWS | J28: New gap-fill. Centralises all security findings for SEBI inspection readiness.
A29: AWS Security Suite — Subtotal | D29: =SUMIF(D21:D28,">0") -> 0 | E29: =SUMIF(E21:E28,">0") -> 0 | F29: =SUMIF(F21:F28,">0") -> 0 | G29: =SUMIF(G21:G28,">0") -> 0
A30: AWS Observability
A31: AWS Observability | B31: AWS X-Ray (APM / distributed tracing) | C31: Replaces Datadog/external APM. PARA-DEBATE agent latency, DB query perf. ~$4-10/mo. Credits cover. | D31: credits | E31: credits | F31: credits | G31: credits | H31: Yes | I31: AWS | J31: Replaces external APM ₹5,000/mo. Saves ₹90,000 over 18 months.
A32: AWS Observability | B32: Route 53 Health Checks + CloudWatch Dashboard | C32: Replaces Betterstack/StatusPage. $0.50/endpoint. SLA uptime evidence for brokerage partners. | D32: credits | E32: credits | F32: credits | G32: credits | H32: Yes | I32: AWS | J32: Replaces Betterstack ₹1,700/mo. Saves ₹30,600 over 18 months.
A33: AWS Observability — Subtotal | D33: =SUMIF(D31:D32,">0") -> 0 | E33: =SUMIF(E31:E32,">0") -> 0 | F33: =SUMIF(F31:F32,">0") -> 0 | G33: =SUMIF(G31:G32,">0") -> 0
A34: AWS App Services
A35: AWS App Services | B35: Amazon Cognito (auth — M1 onwards) | C35: Replaces Supabase auth layer. JWT, OAuth, SAML/SSO. Free tier: 10K MAU. ~$0-35/mo. Credits cover. | D35: credits | E35: credits | F35: credits | G35: credits | H35: Yes | I35: AWS | J35: Replaces Supabase auth component. Supabase retained for Postgres + RLS only.
A36: AWS App Services | B36: Amazon SES (transactional + bulk email) | C36: Replaces Resend + Brevo entirely. $0.10/1K emails. 50K/mo = $5. EC2-origin: 62K free/mo. | D36: credits | E36: credits | F36: credits | G36: credits | H36: Yes | I36: AWS | J36: Replaces Resend ($20) + Brevo ($25) = saves $45/mo = ₹45,900 over 18 months.
A37: AWS App Services | B37: Amazon Pinpoint (product analytics + push) | C37: Replaces PostHog. User funnel, event tracking, feature flags via AppConfig. Free tier generous. | D37: credits | E37: credits | F37: credits | G37: credits | H37: Yes | I37: AWS | J37: Replaces PostHog ₹1,690/mo. Activate credits cover usage above free tier.
A38: AWS App Services — Subtotal | D38: =SUMIF(D35:D37,">0") -> 0 | E38: =SUMIF(E35:E37,">0") -> 0 | F38: =SUMIF(F35:F37,">0") -> 0 | G38: =SUMIF(G35:G37,">0") -> 0
A39: Retained SaaS
A40: Retained SaaS | B40: Supabase Pro (DB + RLS only — M1 to M5) | C40: Auth offloaded to Cognito. Supabase Pro ($25/mo) retained for managed Postgres + row-level security. | D40: 2125 | E40: 106250 | F40: 25 | G40: 1250 | H40: No | I40: RETAIN | J40: CORRECTED: Pro only (not Team). Drops from ₹55K to ₹2.1K/mo M1-5. Team from M6 when brokerage BD needs SOC 2.
...

Sheet API Cost Assumptions
A1: NeuralQuant — Claude API Cost Model (Phase-Scaled) + Corrected Assumptions
A2: Blue text = hardcoded inputs | Black text = calculated | Amber = corrected vs original SOW
A3: Section A — Claude Sonnet 4.6 Pricing Constants (verified May 2026)
A4: Parameter | B4: Value | C4: Unit | F4: Source / Notes
A5: Input price (fresh) | B5: 3 | C5: $/MTok | F5: Source: Anthropic pricing — Sonnet 4.6, verified Apr 2026
A6: Output price | B6: 15 | C6: $/MTok | F6: Source: Anthropic pricing — Sonnet 4.6
A7: Cache read price | B7: 0.3 | C7: $/MTok | F7: 90% discount on cached input tokens
A8: USD/INR rate | B8: 85 | C8: ₹/$ | F8: Approximate rate used throughout BOM
A9: Section B — Token Budget per PARA-DEBATE Query (7 agent calls + HEAD ANALYST)
A10: Token component | B10: Tokens | C10: Type | D10: Cost/call ($) | F10: Notes
A11: Agent system prompts (cached) | B11: 42000 | C11: cached_in | D11: =B11/1000000*$B$7 -> 0.0126 | F11: 7 agents × 6,000 tok each
A12: Agent user context (fresh) | B12: 7000 | C12: fresh_in | D12: =B12/1000000*$B$5 -> 0.021 | F12: 7 agents × 1,000 tok each
A13: Agent outputs | B13: 3500 | C13: output | D13: =B13/1000000*$B$6 -> 0.0525 | F13: 7 agents × 500 tok each
A14: HEAD ANALYST cached context | B14: 4000 | C14: cached_in | D14: =B14/1000000*$B$7 -> 0.0012 | F14: Synthesis system prompt
A15: HEAD ANALYST fresh input | B15: 3500 | C15: fresh_in | D15: =B15/1000000*$B$5 -> 0.0105 | F15: All 7 agent outputs as input
A16: HEAD ANALYST output | B16: 800 | C16: output | D16: =B16/1000000*$B$6 -> 0.012 | F16: Composite score + rationale
A17: Cost per query (realistic) | D17: =SUM(D11:D16) -> 0.1098 | F17: SOW claimed $0.029 — actual ~$0.068-0.11 depending on cache efficiency
A19: Section C — Phase-Scaled Monthly Claude API Cost (corrected)
A20: Phase | B20: Months | C20: Queries/day | D20: Days/mo | E20: Monthly queries | F20: Monthly cost ($) | G20: Monthly cost (₹) | H20: SOW ₹/mo | I20: Delta ₹/mo | J20: Notes
A21: M1–3 | B21: 3 | C21: 200 | D21: 30 | E21: =C21*D21 -> 6000 | F21: =(E21*$D$17) -> 658.8 | G21: =F21*$B$8 -> 55998 | H21: 111975 | I21: =G21-H21 -> -55977 | J21: Early users / dev
A22: M4–9 | B22: 6 | C22: 800 | D22: 30 | E22: =C22*D22 -> 24000 | F22: =(E22*$D$17) -> 2635.2 | G22: =F22*$B$8 -> 223992 | H22: 111975 | I22: =G22-H22 -> 112017 | J22: Growth phase
A23: M10–18 | B23: 9 | C23: 2500 | D23: 30 | E23: =C23*D23 -> 75000 | F23: =(E23*$D$17) -> 8235 | G23: =F23*$B$8 -> 699975 | H23: 111975 | I23: =G23-H23 -> 588000 | J23: Scale phase
A24: 18-month total (Claude API) | G24: =G21*B21+G22*B22+G23*B23 -> 7811721 | H24: 2015550 | I24: =G24-H24 -> 5796171 | J24: Positive delta = revised EXCEEDS SOW; will need budget adjustment at M4+
A26: Claude API Costing
A27: Phase | B27: Months | C27: Monthly queries | D27: Total Queries (18M) | E27: Total Cost ($) - 18M | F27: Total Cost (₹) - 18M
A28: M1–3 | B28: 3 | C28: =E21 -> 6000 | D28: =C28*B28 -> 18000 | E28: =D28*$D$17 -> 1976.4 | F28: =E28*$B$8 -> 167994
A29: M4–9 | B29: 6 | C29: =E22 -> 24000 | D29: =C29*B29 -> 144000 | E29: =D29*$D$17 -> 15811.2 | F29: =E29*$B$8 -> 1343952
A30: M10–18 | B30: 9 | C30: =E23 -> 75000 | D30: =C30*B30 -> 675000 | E30: =D30*$D$17 -> 74115 | F30: =E30*$B$8 -> 6299775
A31: 18-month total (Claude API) | C31: =SUM(C28:C30) -> 105000 | D31: =SUM(D28:D30) -> 837000 | E31: =SUM(E28:E30) -> 91902.6 | F31: =SUM(F28:F30) -> 7811721
A33: Supabase (Pro M1-5 → Team M6+) | B33: Months | C33: Monthly Cost / $ | D33: Total 18M-$ | F33: Total Cost (₹) - 18M
A34: M1 -> 5 | B34: 5 | C34: 25 | D34: =C34*B34 -> 125 | F34: =D34*$B$8 -> 10625
A35: M6 -> 18 | B35: =18-5 -> 13 | C35: 599 | D35: =C35*B35 -> 7787 | F35: =D35*$B$8 -> 661895
A36: Total | B36: =SUM(B34:B35) -> 18 | D36: =SUM(D34:D35) -> 7912 | F36: =SUM(F34:F35) -> 672520
A38: Section D — Other Corrected Line Items
A39: Line item | B39: SOW value | C39: Corrected value | D39: Saving/Mo ₹ | E39: 18-mo impact ₹ | F39: Correction rationale
A40: ISM PMI subscription | B40: ₹3,750/mo ($44/mo) | C40: ₹0 — use FRED API (free, 1-day lag) | D40: 3750 | E40: =D40*18 -> 67500 | F40: ISM has no $44/mo API product. FRED (Federal Reserve) provides PMI with 1-day lag free. Adequate for HMM regime model which doesn't require real-time PMI.
A41: Razorpay platform fee | B41: ₹5,000/mo fixed | C41: ₹0 fixed (2% txn fee → COGS only) | D41: 5000 | E41: =D41*18 -> 90000 | F41: Standard Razorpay: zero fixed fee, 2% per txn only. ₹5K/mo = Razorpay X banking suite, unnecessary at launch. 2% txn fee must move to financial model COGS line.
A42: PostHog product analytics | B42: ₹1,690/mo ($20/mo) | C42: ₹0 through M12 (free tier = 1M events/mo) | D42: 1690 | E42: =D42*12 -> 20280 | F42: PostHog free tier covers 1M events/month. NeuralQuant won't exceed this before M12 at projected user volumes. Budget from M13 onward if needed.
A43: Supabase Team (M1–5) | B43: ₹55,000/mo from M1 | C43: ₹2,125/mo (Pro) M1-5, Team from M6 | D43: 52875 | E43: =D43*5 -> 264375 | F43: Supabase Pro ($25/mo) adequate for early-stage. Team ($599/mo) justified only when brokerage partners require SOC 2 compliance evidence — likely M6 BD demos. Saves ~₹2.6L in early months.
A44: Total savings from corrections (18-mo) | E44: =SUM(E40:E43) -> 442155 | F44: Savings partially offset the Claude API overage at scale

Sheet SOW Changes Summary
A1: NeuralQuant — SOW Changes v2→v3 (AWS-First Migration)
A2: Impact of AWS Activate partnership on Statement of Work — scope changes, vendor eliminations, and new AWS-native deliverables
A3: SOW section / deliverable | B3: v2 approach | C3: v3 AWS approach | D3: Financial impact | E3: Action required
A4: Cloud infra — compute, DB, storage | B4: AWS EC2+RDS+Lambda+S3 ($590/mo, flat, undercosted at Multi-AZ) | C4: Same services, correctly scoped Multi-AZ from M6. Full cost absorbed by Activate credits. | D4: ~$82K AWS spend covered by credits. Net BOM cost = ₹0 for all AWS infra. | E4: Apply for AWS Activate Portfolio. Submit credit request in M1 with investor backing evidence.
A5: Cache layer | B5: Upstash Redis (external, $50/mo, ₹4,200/mo) | C5: AWS ElastiCache Redis (cache.t3.micro, ~$20/mo). Native AWS, covered by credits. | D5: Saves ₹75,600 (18mo). Also removes external vendor dependency. | E5: Backend engineer provisions ElastiCache in same VPC as RDS. No code change — same Redis API.
A6: WAF + DDoS protection | B6: Cloudflare Pro (external, $100/mo, ₹8,400/mo) | C6: AWS WAF + Shield Standard (free). WAF ~$18-30/mo. Covered by Activate credits. | D6: Saves ₹1,51,200 (18mo). Shield Standard is free. | E6: Configure AWS WAF Web ACL with managed rule groups (SQLi, XSS, IP reputation). Attach to ALB.
A7: Dependency / vulnerability scanning | B7: Snyk (external, $50/mo, ₹4,200/mo) | C7: Amazon Inspector (continuous EC2+Lambda+ECR scanning, ~$25-45/mo). Credits cover. | D7: Saves ₹75,600 (18mo). Continuous vs Snyk point-in-time. | E7: Enable Inspector in AWS console. Integrate findings with Security Hub. Zero config for Lambda.
A8: Threat detection | B8: Not budgeted — gap | C8: Amazon GuardDuty NEW. ML threat detection: crypto-mining, credential theft, exfil. ~$80-120/mo. | D8: New cost — fully covered by Activate credits. SEBI audit trail value. | E8: Enable GuardDuty in M1. Connect to Security Hub. Set CloudWatch alarm on HIGH severity findings.
A9: PII data protection | B9: DPDP Act compliance = legal setup only (₹75K one-time) | C9: Amazon Macie NEW + legal setup. Macie scans S3 for Aadhaar, PAN, card numbers automatically. | D9: Macie ~$15/mo (credits cover). Legal one-time ₹75K retained. | E9: Enable Macie on all S3 buckets before user PII collection begins. Satisfies DPDP Act 2023 data mapping requirement.
A10: Security findings aggregation | B10: Manual — no central dashboard | C10: AWS Security Hub NEW. Aggregates WAF + GuardDuty + Inspector findings. SOC 2 evidence. | D10: ~$25-35/mo covered by credits. Reduces SOC 2 Type 1 prep effort by ~30%. | E10: Enable Security Hub with CIS AWS Foundations benchmark. Export findings to S3 for auditor.
A11: APM / application performance | B11: Datadog lite / external APM (₹5,000/mo) | C11: AWS X-Ray (native, ~$4-10/mo). Full PARA-DEBATE agent trace waterfall. | D11: Saves ₹90,000 (18mo). X-Ray traces Lambda → FastAPI → RDS chains natively. | E11: Add X-Ray SDK to FastAPI. Instrument each PARA-DEBATE agent call. Zero infra change.
A12: Uptime / StatusPage | B12: Betterstack external (₹1,700/mo) | C12: Route 53 Health Checks + CloudWatch dashboard (~$2-4/mo). Credits cover. | D12: Saves ₹30,600 (18mo). | E12: Create Route 53 health check on API endpoint. Set up CloudWatch dashboard as internal StatusPage.
A13: Authentication | B13: Supabase Team auth (JWT/OAuth/SAML, $599/mo from M1) | C13: Amazon Cognito (JWT/OAuth/SAML/SSO, free <10K MAU). Supabase drops to Pro ($25) DB-only. | D13: Saves ~₹2.6L M1-5. Cognito free tier covers NQ user volumes through M9+. | E13: Frontend engineer implements Cognito User Pool + Identity Pool. Supabase configured for DB+RLS only.
A14: Email delivery | B14: Resend ($20) + Brevo ($25) = $45/mo | C14: Amazon SES only. $0.10/1K emails. 50K/mo = $5. Replaces both vendors. | D14: Saves ₹45,900 (18mo). Single vendor, higher deliverability on EC2-origin sends. | E14: Configure SES domain verification + DKIM. Update transactional email code to use SES SDK.
... A19: Razorpay fixed fee | B19: ₹5,000/mo fixed platform fee (incorrect — not a standard Razorpay charge) | C19: Zero fixed fee. 2% per transaction only. Move to COGS in financial model. | D19: Saves ₹90,000 (18mo in BOM). 2% txn appears in margin waterfall instead. | E19: Update financial model: remove Razorpay from opex, add 2% of Indian subscription revenue to COGS.
